Workbook

Sheet input
A1: FINANCIAL FLOOR DECISION LAB — INPUT
A2: Blue cells = inputs you edit. Do not edit formulas in other sheets.
A4: PROFILE
A5: current_age | B5: 38
A6: monthly_income | B6: 4800
A7: monthly_expense | B7: 3000
A8: cash | B8: 19124
A9: brokerage | B9: 76009
A10: retirement_accounts | B10: 71943
A11: monthly_401k | B11: 1958
A13: RETIREMENT
A14: expected_return | B14: 0.07
A15: withdrawal_rate | B15: 0.04
A16: target_monthly_spend | B16: 8333
A17: social_security_monthly | B17: 0
A18: retirement_invest_mo | B18: 800
A20: GOALS
A21: goal_name | B21: target_amount | C21: monthly_alloc
A22: Trading Seed | B22: 250000 | C22: 200
A23: Grad School Fund | B23: 40000 | C23: 300
A24: House Down Payment | B24: 80000 | C24: 500
A26: SCENARIOS
A27: scenario_name | B27: scenario_type | C27: active_flag | D27: pause_401k | E27: start_offset_yr | F27: duration_mo | G27: income_change_pct | H27: one_time_cost | I27: expense_delta_mo | J27: contrib_delta_mo | K27: recovery_income_pct
A28: Baseline | B28: baseline | C28: =TRUE() -> TRUE | D28: =FALSE() -> FALSE | E28: 0 | F28: 0 | G28: 0 | H28: 0 | I28: 0 | J28: 0 | K28: 1
A29: Career Break 1yr | B29: flow_shock | C29: =TRUE() -> TRUE | D29: =TRUE() -> TRUE | E29: 1 | F29: 12 | G29: -1 | H29: 0 | I29: 0 | J29: -800 | K29: 1
A30: Grad School 2yr | B30: hybrid | C30: =TRUE() -> TRUE | D30: =TRUE() -> TRUE | E30: 2 | F30: 24 | G30: -0.5 | H30: 40000 | I30: 300 | J30: -800 | K30: 1
A31: Family Planning | B31: flow_shock | C31: =TRUE() -> TRUE | D31: =FALSE() -> FALSE | E31: 1 | F31: 12 | G31: 0 | H31: 0 | I31: 500 | J31: 0 | K31: 1

Sheet calc_is
A1: INCOME STATEMENT (IS) — Flow Constraints
A2: INCOME STATEMENT
A3: monthly_income | B3: =input!B6 -> 4800
A4: monthly_expense | B4: =input!B7 -> 3000
A5: surplus | B5: =B3-B4 -> 1800
A7: monthly_401k | B7: =input!B11 -> 1958
A8: annual_401k | B8: =B7*12 -> 23496
A10: cash | B10: =input!B8 -> 19124
A11: brokerage | B11: =input!B9 -> 76009
A12: retirement_accounts | B12: =input!B10 -> 71943
A13: starting_invested_assets | B13: =B11+B12 -> 147952
A14: total_assets | B14: =B10+B11+B12 -> 167076
A16: survival_months | B16: =IFERROR(B10/B4,0) -> 6.3746667
A17: current_age | B17: =input!B5 -> 38

Sheet calc_cf
A1: CASH FLOW (CF) — Allocation Waterfall
A2: ALLOCATION WATERFALL
A3: surplus | B3: =calc_is!B5 -> 1800
A4: mandatory_401k_monthly | B4: =calc_is!B7 -> 1958
A6: retirement_invest_monthly | B6: =input!B18 -> 800
A7: retirement_invest_monthly_cap | B7: =MAX(0,MIN(B6,calc_is!B5)) -> 800
A9: goal_alloc_total_monthly | B9: =SUM(B12:B14) -> 1000
A10: surplus_after_retire | B10: =MAX(0,B3-B7) -> 1000
A11: GOAL ALLOCATION (Surplus-Capped)
A12: =input!C22 -> 200 | B12: =MIN(input!C22, MAX(0, B10)) -> 200 | C12: =IFERROR(input!B22, 0) -> 250000 | D12: =IFERROR((input!B22)/MAX(1,B12)*12, 0) -> 15000
A13: =input!C23 -> 300 | B13: =MIN(input!C23, MAX(0, B10-B12)) -> 300 | C13: =IFERROR(input!B23, 0) -> 40000 | D13: =IFERROR((input!B23)/MAX(1,B13)*12, 0) -> 1600
A14: =input!C24 -> 500 | B14: =MIN(input!C24, MAX(0, B10-B12-B13)) -> 500 | C14: =IFERROR(input!B24, 0) -> 80000 | D14: =IFERROR((input!B24)/MAX(1,B14)*12, 0) -> 1920
A16: GOAL ACHIEVE AGE
A17: goal_name | B17: achieve_age | C17: months_remaining
A18: =input!C22 -> 200 | B18: =IFERROR(input!B5+B12/12, 999) -> 54.666667 | C18: =B12 -> 200
A19: =input!C23 -> 300 | B19: =IFERROR(input!B5+B13/12, 999) -> 63 | C19: =B13 -> 300
A20: =input!C24 -> 500 | B20: =IFERROR(input!B5+B14/12, 999) -> 79.666667 | C20: =B14 -> 500
A22: RESIDUAL CASH
A23: cash_residual_monthly | B23: =MAX(0,B3-B7-B9) -> 0
A24: total_allocated_monthly | B24: =B7+B9 -> 1800

Sheet calc_bs
A1: BALANCE SHEET (BS) — Stock State
A2: CURRENT BALANCE SHEET
A3: cash | B3: =calc_is!B10 -> 19124
A4: brokerage | B4: =calc_is!B11 -> 76009
A5: retirement_accounts | B5: =calc_is!B12 -> 71943
A6: starting_invested_assets | B6: =calc_is!B13 -> 147952
A7: total_assets | B7: =calc_is!B14 -> 167076
A9: safe_layer_target | B9: =calc_metrics!B4 -> 2499900
A10: safe_layer_progress | B10: =IFERROR(B6/B9,0) -> 0.059183167
A11: surplus_allocated_check | B11: =calc_cf!B24 -> 1800

Sheet calc_metrics
A1: METRICS — Primary KPIs
A2: CORE METRICS
A3: target_floor_annual_spend | B3: =input!B16*12 -> 99996
A4: safe_layer_target | B4: =IFERROR((B3-input!B17*12)/input!B15,0) -> 2499900
A5: liquid_invested_assets | B5: =calc_is!B13 -> 147952
A6: safe_layer_progress | B6: =IFERROR(B5/B4,0) -> 0.059183167
A7: survival_months | B7: =calc_is!B16 -> 6.3746667
A9: floor_age | B9: =B16 -> 61
A10: years_to_stability | B10: =IFERROR(B9-input!B5,0) -> 23
A11: investment_rate | B11: =IFERROR((calc_cf!B7+calc_is!B7)*12/(input!B6*12),0) -> 0.57458333
A12: total_monthly_invest | B12: =IFERROR(calc_cf!B7+calc_is!B7,0) -> 2758
A14: SCENARIO SUMMARY
A15: scenario_name | B15: floor_age | C15: delta_vs_baseline
A16: SCN000 | B16: 61 | C16: 0
A17: SCN001 | B17: 61 | C17: 0
A18: SCN002 | B18: 62 | C18: 1
A19: SCN003 | B19: 61 | C19: 0

Sheet projection
A1: scenario_id | B1: scenario_name | C1: projection_year_index | D1: age | E1: age_in_year | F1: income_annual | G1: expense_annual | H1: surplus_annual | I1: contrib_annual | J1: assets_start | K1: assets_end | L1: cash_balance | M1: safe_layer_target | N1: floor_reached_flag | O1: safe_layer_progress | P1: feasible_flag | Q1: survival_months | R1: scenario_type
A2: SCN000 | B2: Baseline | C2: 0 | D2: 0 | E2: =input!B5+0 -> 38 | F2: =input!B6*12 -> 57600 | G2: =input!B7*12 -> 36000 | H2: =F2-G2 -> 21600 | I2: =input!B11*12+MAX(0, MIN(input!B18, H2/12)) * 12 -> 33096 | J2: =calc_is!B13 -> 147952 | K2: =J2*(1+input!B14)+I2*((1+input!B14)-1)/input!B14 -> 191404.64 | L2: =input!B8 -> 19124 | M2: =calc_metrics!B4 -> 2499900 | N2: =IF(K2>=M2,"TRUE","FALSE") -> FALSE | O2: =IFERROR(K2/M2,0) -> 0.076564919 | P2: =IF(AND(L2>=0,Q2>=6,K2>=M2*0.25),"TRUE","FALSE") -> FALSE | Q2: =IFERROR(L2/(input!B7),0) -> 6.3746667 | R2: baseline
A3: SCN000 | B3: Baseline | C3: 1 | D3: 1 | E3: =input!B5+1 -> 39 | F3: =input!B6*12 -> 57600 | G3: =input!B7*12 -> 36000 | H3: =F3-G3 -> 21600 | I3: =input!B11*12+MAX(0, MIN(input!B18, H3/12)) * 12 -> 33096 | J3: =K2 -> 191404.64 | K3: =J3*(1+input!B14)+I3*((1+input!B14)-1)/input!B14 -> 237898.96 | L3: =L2+MAX(0,H3/12) -> 20924 | M3: =calc_metrics!B4 -> 2499900 | N3: =IF(K3>=M3,"TRUE","FALSE") -> FALSE | O3: =IFERROR(K3/M3,0) -> 0.095163392 | P3: =IF(AND(L3>=0,Q3>=6,K3>=M3*0.25),"TRUE","FALSE") -> FALSE | Q3: =IFERROR(L3/(input!B7),0) -> 6.9746667 | R3: baseline
A4: SCN000 | B4: Baseline | C4: 2 | D4: 2 | E4: =input!B5+2 -> 40 | F4: =input!B6*12 -> 57600 | G4: =input!B7*12 -> 36000 | H4: =F4-G4 -> 21600 | I4: =input!B11*12+MAX(0, MIN(input!B18, H4/12)) * 12 -> 33096 | J4: =K3 -> 237898.96 | K4: =J4*(1+input!B14)+I4*((1+input!B14)-1)/input!B14 -> 287647.89 | L4: =L3+MAX(0,H4/12) -> 22724 | M4: =calc_metrics!B4 -> 2499900 | N4: =IF(K4>=M4,"TRUE","FALSE") -> FALSE | O4: =IFERROR(K4/M4,0) -> 0.11506376 | P4: =IF(AND(L4>=0,Q4>=6,K4>=M4*0.25),"TRUE","FALSE") -> FALSE | Q4: =IFERROR(L4/(input!B7),0) -> 7.5746667 | R4: baseline
A5: SCN000 | B5: Baseline | C5: 3 | D5: 3 | E5: =input!B5+3 -> 41 | F5: =input!B6*12 -> 57600 | G5: =input!B7*12 -> 36000 | H5: =F5-G5 -> 21600 | I5: =input!B11*12+MAX(0, MIN(input!B18, H5/12)) * 12 -> 33096 | J5: =K4 -> 287647.89 | K5: =J5*(1+input!B14)+I5*((1+input!B14)-1)/input!B14 -> 340879.24 | L5: =L4+MAX(0,H5/12) -> 24524 | M5: =calc_metrics!B4 -> 2499900 | N5: =IF(K5>=M5,"TRUE","FALSE") -> FALSE | O5: =IFERROR(K5/M5,0) -> 0.13635715 | P5: =IF(AND(L5>=0,Q5>=6,K5>=M5*0.25),"TRUE","FALSE") -> FALSE | Q5: =IFERROR(L5/(input!B7),0) -> 8.1746667 | R5: baseline
A6: SCN000 | B6: Baseline | C6: 4 | D6: 4 | E6: =input!B5+4 -> 42 | F6: =input!B6*12 -> 57600 | G6: =input!B7*12 -> 36000 | H6: =F6-G6 -> 21600 | I6: =input!B11*12+MAX(0, MIN(input!B18, H6/12)) * 12 -> 33096 | J6: =K5 -> 340879.24 | K6: =J6*(1+input!B14)+I6*((1+input!B14)-1)/input!B14 -> 397836.79 | L6: =L5+MAX(0,H6/12) -> 26324 | M6: =calc_metrics!B4 -> 2499900 | N6: =IF(K6>=M6,"TRUE","FALSE") -> FALSE | O6: =IFERROR(K6/M6,0) -> 0.15914108 | P6: =IF(AND(L6>=0,Q6>=6,K6>=M6*0.25),"TRUE","FALSE") -> FALSE | Q6: =IFERROR(L6/(input!B7),0) -> 8.7746667 | R6: baseline
A7: SCN000 | B7: Baseline | C7: 5 | D7: 5 | E7: =input!B5+5 -> 43 | F7: =input!B6*12 -> 57600 | G7: =input!B7*12 -> 36000 | H7: =F7-G7 -> 21600 | I7: =input!B11*12+MAX(0, MIN(input!B18, H7/12)) * 12 -> 33096 | J7: =K6 -> 397836.79 | K7: =J7*(1+input!B14)+I7*((1+input!B14)-1)/input!B14 -> 458781.37 | L7: =L6+MAX(0,H7/12) -> 28124 | M7: =calc_metrics!B4 -> 2499900 | N7: =IF(K7>=M7,"TRUE","FALSE") -> FALSE | O7: =IFERROR(K7/M7,0) -> 0.18351989 | P7: =IF(AND(L7>=0,Q7>=6,K7>=M7*0.25),"TRUE","FALSE") -> FALSE | Q7: =IFERROR(L7/(input!B7),0) -> 9.3746667 | R7: baseline
A8: SCN000 | B8: Baseline | C8: 6 | D8: 6 | E8: =input!B5+6 -> 44 | F8: =input!B6*12 -> 57600 | G8: =input!B7*12 -> 36000 | H8: =F8-G8 -> 21600 | I8: =input!B11*12+MAX(0, MIN(input!B18, H8/12)) * 12 -> 33096 | J8: =K7 -> 458781.37 | K8: =J8*(1+input!B14)+I8*((1+input!B14)-1)/input!B14 -> 523992.06 | L8: =L7+MAX(0,H8/12) -> 29924 | M8: =calc_metrics!B4 -> 2499900 | N8: =IF(K8>=M8,"TRUE","FALSE") -> FALSE | O8: =IFERROR(K8/M8,0) -> 0.20960521 | P8: =IF(AND(L8>=0,Q8>=6,K8>=M8*0.25),"TRUE","FALSE") -> FALSE | Q8: =IFERROR(L8/(input!B7),0) -> 9.9746667 | R8: baseline
A9: SCN000 | B9: Baseline | C9: 7 | D9: 7 | E9: =input!B5+7 -> 45 | F9: =input!B6*12 -> 57600 | G9: =input!B7*12 -> 36000 | H9: =F9-G9 -> 21600 | I9: =input!B11*12+MAX(0, MIN(input!B18, H9/12)) * 12 -> 33096 | J9: =K8 -> 523992.06 | K9: =J9*(1+input!B14)+I9*((1+input!B14)-1)/input!B14 -> 593767.51 | L9: =L8+MAX(0,H9/12) -> 31724 | M9: =calc_metrics!B4 -> 2499900 | N9: =IF(K9>=M9,"TRUE","FALSE") -> FALSE | O9: =IFERROR(K9/M9,0) -> 0.2375165 | P9: =IF(AND(L9>=0,Q9>=6,K9>=M9*0.25),"TRUE","FALSE") -> FALSE | Q9: =IFERROR(L9/(input!B7),0) -> 10.574667 | R9: baseline
A10: SCN000 | B10: Baseline | C10: 8 | D10: 8 | E10: =input!B5+8 -> 46 | F10: =input!B6*12 -> 57600 | G10: =input!B7*12 -> 36000 | H10: =F10-G10 -> 21600 | I10: =input!B11*12+MAX(0, MIN(input!B18, H10/12)) * 12 -> 33096 | J10: =K9 -> 593767.51 | K10: =J10*(1+input!B14)+I10*((1+input!B14)-1)/input!B14 -> 668427.23 | L10: =L9+MAX(0,H10/12) -> 33524 | M10: =calc_metrics!B4 -> 2499900 | N10: =IF(K10>=M10,"TRUE","FALSE") -> FALSE | O10: =IFERROR(K10/M10,0) -> 0.26738159 | P10: =IF(AND(L10>=0,Q10>=6,K10>=M10*0.25),"TRUE","FALSE") -> TRUE | Q10: =IFERROR(L10/(input!B7),0) -> 11.174667 | R10: baseline
A11: SCN000 | B11: Baseline | C11: 9 | D11: 9 | E11: =input!B5+9 -> 47 | F11: =input!B6*12 -> 57600 | G11: =input!B7*12 -> 36000 | H11: =F11-G11 -> 21600 | I11: =input!B11*12+MAX(0, MIN(input!B18, H11/12)) * 12 -> 33096 | J11: =K10 -> 668427.23 | K11: =J11*(1+input!B14)+I11*((1+input!B14)-1)/input!B14 -> 748313.14 | L11: =L10+MAX(0,H11/12) -> 35324 | M11: =calc_metrics!B4 -> 2499900 | N11: =IF(K11>=M11,"TRUE","FALSE") -> FALSE | O11: =IFERROR(K11/M11,0) -> 0.29933723 | P11: =IF(AND(L11>=0,Q11>=6,K11>=M11*0.25),"TRUE","FALSE") -> TRUE | Q11: =IFERROR(L11/(input!B7),0) -> 11.774667 | R11: baseline
A12: SCN000 | B12: Baseline | C12: 10 | D12: 10 | E12: =input!B5+10 -> 48 | F12: =input!B6*12 -> 57600 | G12: =input!B7*12 -> 36000 | H12: =F12-G12 -> 21600 | I12: =input!B11*12+MAX(0, MIN(input!B18, H12/12)) * 12 -> 33096 | J12: =K11 -> 748313.14 | K12: =J12*(1+input!B14)+I12*((1+input!B14)-1)/input!B14 -> 833791.06 | L12: =L11+MAX(0,H12/12) -> 37124 | M12: =calc_metrics!B4 -> 2499900 | N12: =IF(K12>=M12,"TRUE","FALSE") -> FALSE | O12: =IFERROR(K12/M12,0) -> 0.33352976 | P12: =IF(AND(L12>=0,Q12>=6,K12>=M12*0.25),"TRUE","FALSE") -> TRUE | Q12: =IFERROR(L12/(input!B7),0) -> 12.374667 | R12: baseline
A13: SCN000 | B13: Baseline | C13: 11 | D13: 11 | E13: =input!B5+11 -> 49 | F13: =input!B6*12 -> 57600 | G13: =input!B7*12 -> 36000 | H13: =F13-G13 -> 21600 | I13: =input!B11*12+MAX(0, MIN(input!B18, H13/12)) * 12 -> 33096 | J13: =K12 -> 833791.06 | K13: =J13*(1+input!B14)+I13*((1+input!B14)-1)/input!B14 -> 925252.43 | L13: =L12+MAX(0,H13/12) -> 38924 | M13: =calc_metrics!B4 -> 2499900 | N13: =IF(K13>=M13,"TRUE","FALSE") -> FALSE | O13: =IFERROR(K13/M13,0) -> 0.37011578 | P13: =IF(AND(L13>=0,Q13>=6,K13>=M13*0.25),"TRUE","FALSE") -> TRUE | Q13: =IFERROR(L13/(input!B7),0) -> 12.974667 | R13: baseline
A14: SCN000 | B14: Baseline | C14: 12 | D14: 12 | E14: =input!B5+12 -> 50 | F14: =input!B6*12 -> 57600 | G14: =input!B7*12 -> 36000 | H14: =F14-G14 -> 21600 | I14: =input!B11*12+MAX(0, MIN(input!B18, H14/12)) * 12 -> 33096 | J14: =K13 -> 925252.43 | K14: =J14*(1+input!B14)+I14*((1+input!B14)-1)/input!B14 -> 1023116.1 | L14: =L13+MAX(0,H14/12) -> 40724 | M14: =calc_metrics!B4 -> 2499900 | N14: =IF(K14>=M14,"TRUE","FALSE") -> FALSE | O14: =IFERROR(K14/M14,0) -> 0.40926281 | P14: =IF(AND(L14>=0,Q14>=6,K14>=M14*0.25),"TRUE","FALSE") -> TRUE | Q14: =IFERROR(L14/(input!B7),0) -> 13.574667 | R14: baseline
A15: SCN000 | B15: Baseline | C15: 13 | D15: 13 | E15: =input!B5+13 -> 51 | F15: =input!B6*12 -> 57600 | G15: =input!B7*12 -> 36000 | H15: =F15-G15 -> 21600 | I15: =input!B11*12+MAX(0, MIN(input!B18, H15/12)) * 12 -> 33096 | J15: =K14 -> 1023116.1 | K15: =J15*(1+input!B14)+I15*((1+input!B14)-1)/input!B14 -> 1127830.2 | L15: =L14+MAX(0,H15/12) -> 42524 | M15: =calc_metrics!B4 -> 2499900 | N15: =IF(K15>=M15,"TRUE","FALSE") -> FALSE | O15: =IFERROR(K15/M15,0) -> 0.45115014 | P15: =IF(AND(L15>=0,Q15>=6,K15>=M15*0.25),"TRUE","FALSE") -> TRUE | Q15: =IFERROR(L15/(input!B7),0) -> 14.174667 | R15: baseline
A16: SCN000 | B16: Baseline | C16: 14 | D16: 14 | E16: =input!B5+14 -> 52 | F16: =input!B6*12 -> 57600 | G16: =input!B7*12 -> 36000 | H16: =F16-G16 -> 21600 | I16: =input!B11*12+MAX(0, MIN(input!B18, H16/12)) * 12 -> 33096 | J16: =K15 -> 1127830.2 | K16: =J16*(1+input!B14)+I16*((1+input!B14)-1)/input!B14 -> 1239874.3 | L16: =L15+MAX(0,H16/12) -> 44324 | M16: =calc_metrics!B4 -> 2499900 | N16: =IF(K16>=M16,"TRUE","FALSE") -> FALSE | O16: =IFERROR(K16/M16,0) -> 0.49596958 | P16: =IF(AND(L16>=0,Q16>=6,K16>=M16*0.25),"TRUE","FALSE") -> TRUE | Q16: =IFERROR(L16/(input!B7),0) -> 14.774667 | R16: baseline
A17: SCN000 | B17: Baseline | C17: 15 | D17: 15 | E17: =input!B5+15 -> 53 | F17: =input!B6*12 -> 57600 | G17: =input!B7*12 -> 36000 | H17: =F17-G17 -> 21600 | I17: =input!B11*12+MAX(0, MIN(input!B18, H17/12)) * 12 -> 33096 | J17: =K16 -> 1239874.3 | K17: =J17*(1+input!B14)+I17*((1+input!B14)-1)/input!B14 -> 1359761.6 | L17: =L16+MAX(0,H17/12) -> 46124 | M17: =calc_metrics!B4 -> 2499900 | N17: =IF(K17>=M17,"TRUE","FALSE") -> FALSE | O17: =IFERROR(K17/M17,0) -> 0.54392638 | P17: =IF(AND(L17>=0,Q17>=6,K17>=M17*0.25),"TRUE","FALSE") -> TRUE | Q17: =IFERROR(L17/(input!B7),0) -> 15.374667 | R17: baseline
A18: SCN000 | B18: Baseline | C18: 16 | D18: 16 | E18: =input!B5+16 -> 54 | F18: =input!B6*12 -> 57600 | G18: =input!B7*12 -> 36000 | H18: =F18-G18 -> 21600 | I18: =input!B11*12+MAX(0, MIN(input!B18, H18/12)) * 12 -> 33096 | J18: =K17 -> 1359761.6 | K18: =J18*(1+input!B14)+I18*((1+input!B14)-1)/input!B14 -> 1488040.9 | L18: =L17+MAX(0,H18/12) -> 47924 | M18: =calc_metrics!B4 -> 2499900 | N18: =IF(K18>=M18,"TRUE","FALSE") -> FALSE | O18: =IFERROR(K18/M18,0) -> 0.59524015 | P18: =IF(AND(L18>=0,Q18>=6,K18>=M18*0.25),"TRUE","FALSE") -> TRUE | Q18: =IFERROR(L18/(input!B7),0) -> 15.974667 | R18: baseline
A19: SCN000 | B19: Baseline | C19: 17 | D19: 17 | E19: =input!B5+17 -> 55 | F19: =input!B6*12 -> 57600 | G19: =input!B7*12 -> 36000 | H19: =F19-G19 -> 21600 | I19: =input!B11*12+MAX(0, MIN(input!B18, H19/12)) * 12 -> 33096 | J19: =K18 -> 1488040.9 | K19: =J19*(1+input!B14)+I19*((1+input!B14)-1)/input!B14 -> 1625299.7 | L19: =L18+MAX(0,H19/12) -> 49724 | M19: =calc_metrics!B4 -> 2499900 | N19: =IF(K19>=M19,"TRUE","FALSE") -> FALSE | O19: =IFERROR(K19/M19,0) -> 0.65014589 | P19: =IF(AND(L19>=0,Q19>=6,K19>=M19*0.25),"TRUE","FALSE") -> TRUE | Q19: =IFERROR(L19/(input!B7),0) -> 16.574667 | R19: baseline
A20: SCN000 | B20: Baseline | C20: 18 | D20: 18 | E20: =input!B5+18 -> 56 | F20: =input!B6*12 -> 57600 | G20: =input!B7*12 -> 36000 | H20: =F20-G20 -> 21600 | I20: =input!B11*12+MAX(0, MIN(input!B18, H20/12)) * 12 -> 33096 | J20: =K19 -> 1625299.7 | K20: =J20*(1+input!B14)+I20*((1+input!B14)-1)/input!B14 -> 1772166.7 | L20: =L19+MAX(0,H20/12) -> 51524 | M20: =calc_metrics!B4 -> 2499900 | N20: =IF(K20>=M20,"TRUE","FALSE") -> FALSE | O20: =IFERROR(K20/M20,0) -> 0.70889504 | P20: =IF(AND(L20>=0,Q20>=6,K20>=M20*0.25),"TRUE","FALSE") -> TRUE | Q20: =IFERROR(L20/(input!B7),0) -> 17.174667 | R20: baseline
A21: SCN000 | B21: Baseline | C21: 19 | D21: 19 | E21: =input!B5+19 -> 57 | F21: =input!B6*12 -> 57600 | G21: =input!B7*12 -> 36000 | H21: =F21-G21 -> 21600 | I21: =input!B11*12+MAX(0, MIN(input!B18, H21/12)) * 12 -> 33096 | J21: =K20 -> 1772166.7 | K21: =J21*(1+input!B14)+I21*((1+input!B14)-1)/input!B14 -> 1929314.4 | L21: =L20+MAX(0,H21/12) -> 53324 | M21: =calc_metrics!B4 -> 2499900 | N21: =IF(K21>=M21,"TRUE","FALSE") -> FALSE | O21: =IFERROR(K21/M21,0) -> 0.77175662 | P21: =IF(AND(L21>=0,Q21>=6,K21>=M21*0.25),"TRUE","FALSE") -> TRUE | Q21: =IFERROR(L21/(input!B7),0) -> 17.774667 | R21: baseline
A22: SCN000 | B22: Baseline | C22: 20 | D22: 20 | E22: =input!B5+20 -> 58 | F22: =input!B6*12 -> 57600 | G22: =input!B7*12 -> 36000 | H22: =F22-G22 -> 21600 | I22: =input!B11*12+MAX(0, MIN(input!B18, H22/12)) * 12 -> 33096 | J22: =K21 -> 1929314.4 | K22: =J22*(1+input!B14)+I22*((1+input!B14)-1)/input!B14 -> 2097462.4 | L22: =L21+MAX(0,H22/12) -> 55124 | M22: =calc_metrics!B4 -> 2499900 | N22: =IF(K22>=M22,"TRUE","FALSE") -> FALSE | O22: =IFERROR(K22/M22,0) -> 0.83901851 | P22: =IF(AND(L22>=0,Q22>=6,K22>=M22*0.25),"TRUE","FALSE") -> TRUE | Q22: =IFERROR(L22/(input!B7),0) -> 18.374667 | R22: baseline
A23: SCN000 | B23: Baseline | C23: 21 | D23: 21 | E23: =input!B5+21 -> 59 | F23: =input!B6*12 -> 57600 | G23: =input!B7*12 -> 36000 | H23: =F23-G23 -> 21600 | I23: =input!B11*12+MAX(0, MIN(input!B18, H23/12)) * 12 -> 33096 | J23: =K22 -> 2097462.4 | K23: =J23*(1+input!B14)+I23*((1+input!B14)-1)/input!B14 -> 2277380.7 | L23: =L22+MAX(0,H23/12) -> 56924 | M23: =calc_metrics!B4 -> 2499900 | N23: =IF(K23>=M23,"TRUE","FALSE") -> FALSE | O23: =IFERROR(K23/M23,0) -> 0.91098874 | P23: =IF(AND(L23>=0,Q23>=6,K23>=M23*0.25),"TRUE","FALSE") -> TRUE | Q23: =IFERROR(L23/(input!B7),0) -> 18.974667 | R23: baseline
A24: SCN000 | B24: Baseline | C24: 22 | D24: 22 | E24: =input!B5+22 -> 60 | F24: =input!B6*12 -> 57600 | G24: =input!B7*12 -> 36000 | H24: =F24-G24 -> 21600 | I24: =input!B11*12+MAX(0, MIN(input!B18, H24/12)) * 12 -> 33096 | J24: =K23 -> 2277380.7 | K24: =J24*(1+input!B14)+I24*((1+input!B14)-1)/input!B14 -> 2469893.4 | L24: =L23+MAX(0,H24/12) -> 58724 | M24: =calc_metrics!B4 -> 2499900 | N24: =IF(K24>=M24,"TRUE","FALSE") -> FALSE | O24: =IFERROR(K24/M24,0) -> 0.98799688 | P24: =IF(AND(L24>=0,Q24>=6,K24>=M24*0.25),"TRUE","FALSE") -> TRUE | Q24: =IFERROR(L24/(input!B7),0) -> 19.574667 | R24: baseline
A25: SCN000 | B25: Baseline | C25: 23 | D25: 23 | E25: =input!B5+23 -> 61 | F25: =input!B6*12 -> 57600 | G25: =input!B7*12 -> 36000 | H25: =F25-G25 -> 21600 | I25: =input!B11*12+MAX(0, MIN(input!B18, H25/12)) * 12 -> 33096 | J25: =K24 -> 2469893.4 | K25: =J25*(1+input!B14)+I25*((1+input!B14)-1)/input!B14 -> 2675881.9 | L25: =L24+MAX(0,H25/12) -> 60524 | M25: =calc_metrics!B4 -> 2499900 | N25: =IF(K25>=M25,"TRUE","FALSE") -> TRUE | O25: =IFERROR(K25/M25,0) -> 1.0703956 | P25: =IF(AND(L25>=0,Q25>=6,K25>=M25*0.25),"TRUE","FALSE") -> TRUE | Q25: =IFERROR(L25/(input!B7),0) -> 20.174667 | R25: baseline
A26: SCN000 | B26: Baseline | C26: 24 | D26: 24 | E26: =input!B5+24 -> 62 | F26: =input!B6*12 -> 57600 | G26: =input!B7*12 -> 36000 | H26: =F26-G26 -> 21600 | I26: =input!B11*12+MAX(0, MIN(input!B18, H26/12)) * 12 -> 33096 | J26: =K25 -> 2675881.9 | K26: =J26*(1+input!B14)+I26*((1+input!B14)-1)/input!B14 -> 2896289.7 | L26: =L25+MAX(0,H26/12) -> 62324 | M26: =calc_metrics!B4 -> 2499900 | N26: =IF(K26>=M26,"TRUE","FALSE") -> TRUE | O26: =IFERROR(K26/M26,0) -> 1.1585622 | P26: =IF(AND(L26>=0,Q26>=6,K26>=M26*0.25),"TRUE","FALSE") -> TRUE | Q26: =IFERROR(L26/(input!B7),0) -> 20.774667 | R26: baseline
A27: SCN000 | B27: Baseline | C27: 25 | D27: 25 | E27: =input!B5+25 -> 63 | F27: =input!B6*12 -> 57600 | G27: =input!B7*12 -> 36000 | H27: =F27-G27 -> 21600 | I27: =input!B11*12+MAX(0, MIN(input!B18, H27/12)) * 12 -> 33096 | J27: =K26 -> 2896289.7 | K27: =J27*(1+input!B14)+I27*((1+input!B14)-1)/input!B14 -> 3132125.9 | L27: =L26+MAX(0,H27/12) -> 64124 | M27: =calc_metrics!B4 -> 2499900 | N27: =IF(K27>=M27,"TRUE","FALSE") -> TRUE | O27: =IFERROR(K27/M27,0) -> 1.2529005 | P27: =IF(AND(L27>=0,Q27>=6,K27>=M27*0.25),"TRUE","FALSE") -> TRUE | Q27: =IFERROR(L27/(input!B7),0) -> 21.374667 | R27: baseline
A28: SCN000 | B28: Baseline | C28: 26 | D28: 26 | E28: =input!B5+26 -> 64 | F28: =input!B6*12 -> 57600 | G28: =input!B7*12 -> 36000 | H28: =F28-G28 -> 21600 | I28: =input!B11*12+MAX(0, MIN(input!B18, H28/12)) * 12 -> 33096 | J28: =K27 -> 3132125.9 | K28: =J28*(1+input!B14)+I28*((1+input!B14)-1)/input!B14 -> 3384470.8 | L28: =L27+MAX(0,H28/12) -> 65924 | M28: =calc_metrics!B4 -> 2499900 | N28: =IF(K28>=M28,"TRUE","FALSE") -> TRUE | O28: =IFERROR(K28/M28,0) -> 1.3538425 | P28: =IF(AND(L28>=0,Q28>=6,K28>=M28*0.25),"TRUE","FALSE") -> TRUE | Q28: =IFERROR(L28/(input!B7),0) -> 21.974667 | R28: baseline
A29: SCN000 | B29: Baseline | C29: 27 | D29: 27 | E29: =input!B5+27 -> 65 | F29: =input!B6*12 -> 57600 | G29: =input!B7*12 -> 36000 | H29: =F29-G29 -> 21600 | I29: =input!B11*12+MAX(0, MIN(input!B18, H29/12)) * 12 -> 33096 | J29: =K28 -> 3384470.8 | K29: =J29*(1+input!B14)+I29*((1+input!B14)-1)/input!B14 -> 3654479.7 | L29: =L28+MAX(0,H29/12) -> 67724 | M29: =calc_metrics!B4 -> 2499900 | N29: =IF(K29>=M29,"TRUE","FALSE") -> TRUE | O29: =IFERROR(K29/M29,0) -> 1.4618504 | P29: =IF(AND(L29>=0,Q29>=6,K29>=M29*0.25),"TRUE","FALSE") -> TRUE | Q29: =IFERROR(L29/(input!B7),0) -> 22.574667 | R29: baseline
A30: SCN000 | B30: Baseline | C30: 28 | D30: 28 | E30: =input!B5+28 -> 66 | F30: =input!B6*12 -> 57600 | G30: =input!B7*12 -> 36000 | H30: =F30-G30 -> 21600 | I30: =input!B11*12+MAX(0, MIN(input!B18, H30/12)) * 12 -> 33096 | J30: =K29 -> 3654479.7 | K30: =J30*(1+input!B14)+I30*((1+input!B14)-1)/input!B14 -> 3943389.3 | L30: =L29+MAX(0,H30/12) -> 69524 | M30: =calc_metrics!B4 -> 2499900 | N30: =IF(K30>=M30,"TRUE","FALSE") -> TRUE | O30: =IFERROR(K30/M30,0) -> 1.5774188 | P30: =IF(AND(L30>=0,Q30>=6,K30>=M30*0.25),"TRUE","FALSE") -> TRUE | Q30: =IFERROR(L30/(input!B7),0) -> 23.174667 | R30: baseline
A31: SCN000 | B31: Baseline | C31: 29 | D31: 29 | E31: =input!B5+29 -> 67 | F31: =input!B6*12 -> 57600 | G31: =input!B7*12 -> 36000 | H31: =F31-G31 -> 21600 | I31: =input!B11*12+MAX(0, MIN(input!B18, H31/12)) * 12 -> 33096 | J31: =K30 -> 3943389.3 | K31: =J31*(1+input!B14)+I31*((1+input!B14)-1)/input!B14 -> 4252522.5 | L31: =L30+MAX(0,H31/12) -> 71324 | M31: =calc_metrics!B4 -> 2499900 | N31: =IF(K31>=M31,"TRUE","FALSE") -> TRUE | O31: =IFERROR(K31/M31,0) -> 1.7010771 | P31: =IF(AND(L31>=0,Q31>=6,K31>=M31*0.25),"TRUE","FALSE") -> TRUE | Q31: =IFERROR(L31/(input!B7),0) -> 23.774667 | R31: baseline
A32: SCN000 | B32: Baseline | C32: 30 | D32: 30 | E32: =input!B5+30 -> 68 | F32: =input!B6*12 -> 57600 | G32: =input!B7*12 -> 36000 | H32: =F32-G32 -> 21600 | I32: =input!B11*12+MAX(0, MIN(input!B18, H32/12)) * 12 -> 33096 | J32: =K31 -> 4252522.5 | K32: =J32*(1+input!B14)+I32*((1+input!B14)-1)/input!B14 -> 4583295.1 | L32: =L31+MAX(0,H32/12) -> 73124 | M32: =calc_metrics!B4 -> 2499900 | N32: =IF(K32>=M32,"TRUE","FALSE") -> TRUE | O32: =IFERROR(K32/M32,0) -> 1.8333914 | P32: =IF(AND(L32>=0,Q32>=6,K32>=M32*0.25),"TRUE","FALSE") -> TRUE | Q32: =IFERROR(L32/(input!B7),0) -> 24.374667 | R32: baseline
A33: SCN000 | B33: Baseline | C33: 31 | D33: 31 | E33: =input!B5+31 -> 69 | F33: =input!B6*12 -> 57600 | G33: =input!B7*12 -> 36000 | H33: =F33-G33 -> 21600 | I33: =input!B11*12+MAX(0, MIN(input!B18, H33/12)) * 12 -> 33096 | J33: =K32 -> 4583295.1 | K33: =J33*(1+input!B14)+I33*((1+input!B14)-1)/input!B14 -> 4937221.8 | L33: =L32+MAX(0,H33/12) -> 74924 | M33: =calc_metrics!B4 -> 2499900 | N33: =IF(K33>=M33,"TRUE","FALSE") -> TRUE | O33: =IFERROR(K33/M33,0) -> 1.9749677 | P33: =IF(AND(L33>=0,Q33>=6,K33>=M33*0.25),"TRUE","FALSE") -> TRUE | Q33: =IFERROR(L33/(input!B7),0) -> 24.974667 | R33: baseline
A34: SCN000 | B34: Baseline | C34: 32 | D34: 32 | E34: =input!B5+32 -> 70 | F34: =input!B6*12 -> 57600 | G34: =input!B7*12 -> 36000 | H34: =F34-G34 -> 21600 | I34: =input!B11*12+MAX(0, MIN(input!B18, H34/12)) * 12 -> 33096 | J34: =K33 -> 4937221.8 | K34: =J34*(1+input!B14)+I34*((1+input!B14)-1)/input!B14 -> 5315923.3 | L34: =L33+MAX(0,H34/12) -> 76724 | M34: =calc_metrics!B4 -> 2499900 | N34: =IF(K34>=M34,"TRUE","FALSE") -> TRUE | O34: =IFERROR(K34/M34,0) -> 2.1264544 | P34: =IF(AND(L34>=0,Q34>=6,K34>=M34*0.25),"TRUE","FALSE") -> TRUE | Q34: =IFERROR(L34/(input!B7),0) -> 25.574667 | R34: baseline
A35: SCN000 | B35: Baseline | C35: 33 | D35: 33 | E35: =input!B5+33 -> 71 | F35: =input!B6*12 -> 57600 | G35: =input!B7*12 -> 36000 | H35: =F35-G35 -> 21600 | I35: =input!B11*12+MAX(0, MIN(input!B18, H35/12)) * 12 -> 33096 | J35: =K34 -> 5315923.3 | K35: =J35*(1+input!B14)+I35*((1+input!B14)-1)/input!B14 -> 5721133.9 | L35: =L34+MAX(0,H35/12) -> 78524 | M35: =calc_metrics!B4 -> 2499900 | N35: =IF(K35>=M35,"TRUE","FALSE") -> TRUE | O35: =IFERROR(K35/M35,0) -> 2.2885451 | P35: =IF(AND(L35>=0,Q35>=6,K35>=M35*0.25),"TRUE","FALSE") -> TRUE | Q35: =IFERROR(L35/(input!B7),0) -> 26.174667 | R35: baseline
A36: SCN000 | B36: Baseline | C36: 34 | D36: 34 | E36: =input!B5+34 -> 72 | F36: =input!B6*12 -> 57600 | G36: =input!B7*12 -> 36000 | H36: =F36-G36 -> 21600 | I36: =input!B11*12+MAX(0, MIN(input!B18, H36/12)) * 12 -> 33096 | J36: =K35 -> 5721133.9 | K36: =J36*(1+input!B14)+I36*((1+input!B14)-1)/input!B14 -> 6154709.3 | L36: =L35+MAX(0,H36/12) -> 80324 | M36: =calc_metrics!B4 -> 2499900 | N36: =IF(K36>=M36,"TRUE","FALSE") -> TRUE | O36: =IFERROR(K36/M36,0) -> 2.4619822 | P36: =IF(AND(L36>=0,Q36>=6,K36>=M36*0.25),"TRUE","FALSE") -> TRUE | Q36: =IFERROR(L36/(input!B7),0) -> 26.774667 | R36: baseline
A37: SCN000 | B37: Baseline | C37: 35 | D37: 35 | E37: =input!B5+35 -> 73 | F37: =input!B6*12 -> 57600 | G37: =input!B7*12 -> 36000 | H37: =F37-G37 -> 21600 | I37: =input!B11*12+MAX(0, MIN(input!B18, H37/12)) * 12 -> 33096 | J37: =K36 -> 6154709.3 | K37: =J37*(1+input!B14)+I37*((1+input!B14)-1)/input!B14 -> 6618635 | L37: =L36+MAX(0,H37/12) -> 82124 | M37: =calc_metrics!B4 -> 2499900 | N37: =IF(K37>=M37,"TRUE","FALSE") -> TRUE | O37: =IFERROR(K37/M37,0) -> 2.6475599 | P37: =IF(AND(L37>=0,Q37>=6,K37>=M37*0.25),"TRUE","FALSE") -> TRUE | Q37: =IFERROR(L37/(input!B7),0) -> 27.374667 | R37: baseline
A38: SCN000 | B38: Baseline | C38: 36 | D38: 36 | E38: =input!B5+36 -> 74 | F38: =input!B6*12 -> 57600 | G38: =input!B7*12 -> 36000 | H38: =F38-G38 -> 21600 | I38: =input!B11*12+MAX(0, MIN(input!B18, H38/12)) * 12 -> 33096 | J38: =K37 -> 6618635 | K38: =J38*(1+input!B14)+I38*((1+input!B14)-1)/input!B14 -> 7115035.4 | L38: =L37+MAX(0,H38/12) -> 83924 | M38: =calc_metrics!B4 -> 2499900 | N38: =IF(K38>=M38,"TRUE","FALSE") -> TRUE | O38: =IFERROR(K38/M38,0) -> 2.846128 | P38: =IF(AND(L38>=0,Q38>=6,K38>=M38*0.25),"TRUE","FALSE") -> TRUE | Q38: =IFERROR(L38/(input!B7),0) -> 27.974667 | R38: baseline
A39: SCN000 | B39: Baseline | C39: 37 | D39: 37 | E39: =input!B5+37 -> 75 | F39: =input!B6*12 -> 57600 | G39: =input!B7*12 -> 36000 | H39: =F39-G39 -> 21600 | I39: =input!B11*12+MAX(0, MIN(input!B18, H39/12)) * 12 -> 33096 | J39: =K38 -> 7115035.4 | K39: =J39*(1+input!B14)+I39*((1+input!B14)-1)/input!B14 -> 7646183.9 | L39: =L38+MAX(0,H39/12) -> 85724 | M39: =calc_metrics!B4 -> 2499900 | N39: =IF(K39>=M39,"TRUE","FALSE") -> TRUE | O39: =IFERROR(K39/M39,0) -> 3.0585959 | P39: =IF(AND(L39>=0,Q39>=6,K39>=M39*0.25),"TRUE","FALSE") -> TRUE | Q39: =IFERROR(L39/(input!B7),0) -> 28.574667 | R39: baseline
A40: SCN000 | B40: Baseline | C40: 38 | D40: 38 | E40: =input!B5+38 -> 76 | F40: =input!B6*12 -> 57600 | G40: =input!B7*12 -> 36000 | H40: =F40-G40 -> 21600 | I40: =input!B11*12+MAX(0, MIN(input!B18, H40/12)) * 12 -> 33096 | J40: =K39 -> 7646183.9 | K40: =J40*(1+input!B14)+I40*((1+input!B14)-1)/input!B14 -> 8214512.8 | L40: =L39+MAX(0,H40/12) -> 87524 | M40: =calc_metrics!B4 -> 2499900 | N40: =IF(K40>=M40,"TRUE","FALSE") -> TRUE | O40: =IFERROR(K40/M40,0) -> 3.2859365 | P40: =IF(AND(L40>=0,Q40>=6,K40>=M40*0.25),"TRUE","FALSE") -> TRUE | Q40: =IFERROR(L40/(input!B7),0) -> 29.174667 | R40: baseline
...

Sheet scenarios_def
A1: SCENARIO DEFINITIONS (reference only — edit in input sheet)
A2: scenario_id | B2: scenario_name | C2: scenario_type | D2: active_flag | E2: pause_401k | F2: start_offset_yr | G2: duration_mo | H2: income_change_pct | I2: one_time_cost | J2: expense_delta_mo | K2: recovery_income_pct
A3: SCN000 | B3: =input!A28 -> Baseline | C3: =input!B28 -> baseline | D3: =input!C28 -> TRUE | E3: =input!D28 -> FALSE | F3: =input!E28 -> 0 | G3: =input!F28 -> 0 | H3: =input!G28 -> 0 | I3: =input!H28 -> 0 | ... K3: =input!J28 -> 0
A4: SCN001 | B4: =input!A29 -> Career Break 1yr | C4: =input!B29 -> flow_shock | D4: =input!C29 -> TRUE | E4: =input!D29 -> TRUE | F4: =input!E29 -> 1 | G4: =input!F29 -> 12 | H4: =input!G29 -> -1 | I4: =input!H29 -> 0 | ... K4: =input!J29 -> -800
A5: SCN002 | B5: =input!A30 -> Grad School 2yr | C5: =input!B30 -> hybrid | D5: =input!C30 -> TRUE | E5: =input!D30 -> TRUE | F5: =input!E30 -> 2 | G5: =input!F30 -> 24 | H5: =input!G30 -> -0.5 | I5: =input!H30 -> 40000 | ... K5: =input!J30 -> -800
A6: SCN003 | B6: =input!A31 -> Family Planning | C6: =input!B31 -> flow_shock | D6: =input!C31 -> TRUE | E6: =input!D31 -> FALSE | F6: =input!E31 -> 1 | G6: =input!F31 -> 12 | H6: =input!G31 -> 0 | I6: =input!H31 -> 0 | ... K6: =input!J31 -> 0
A8: scenario_type ENUM: baseline | flow_shock | stock_shock | hybrid
A9: flow_shock: IS impact (income/expense change) | stock_shock: BS direct (one_time_cost) | hybrid: both
